Workbook

Sheet 刷题记录
A1: 周 | B1: 模块 | C1: 题目编号 | D1: 题名 | E1: 难度 | F1: 一刷日期 | G1: 一刷用时(分钟) | H1: 掌握度 | I1: 是否二刷 | J1: 二刷日期 | K1: 二刷用时(分钟) | L1: 备注
A2: 1 | B2: Array & Hashing 数组与哈希 | C2: 217 | D2: Contains Duplicate | E2: Easy | F2: 计划前已做 | I2: =IF(OR(K2<>"",J2<>""),"是",IF(OR(G2<>"",F2<>""),"否",""))
A3: 1 | B3: Array & Hashing 数组与哈希 | C3: 242 | D3: Valid Anagram | E3: Easy | F3: 46311 | I3: =IF(OR(K3<>"",J3<>""),"是",IF(OR(G3<>"",F3<>""),"否",""))
A4: 1 | B4: Array & Hashing 数组与哈希 | C4: 1 | D4: Two Sum | E4: Easy | F4: 计划前已做 | I4: =IF(OR(K4<>"",J4<>""),"是",IF(OR(G4<>"",F4<>""),"否",""))
A5: 1 | B5: Array & Hashing 数组与哈希 | C5: 409 | D5: Longest Palindrome | E5: Easy | F5: 计划前已做 | I5: =IF(OR(K5<>"",J5<>""),"是",IF(OR(G5<>"",F5<>""),"否",""))
A6: 1 | B6: Array & Hashing 数组与哈希 | C6: 49 | D6: Group Anagrams | E6: Medium | F6: 计划前已做 | I6: =IF(OR(K6<>"",J6<>""),"是",IF(OR(G6<>"",F6<>""),"否",""))
A7: 1 | B7: Array & Hashing 数组与哈希 | C7: 347 | D7: Top K Frequent Elements | E7: Medium | F7: 计划前已做 | I7: =IF(OR(K7<>"",J7<>""),"是",IF(OR(G7<>"",F7<>""),"否",""))
A8: 1 | B8: Array & Hashing 数组与哈希 | C8: 271 | D8: Encode and Decode Strings | E8: Medium | I8: =IF(OR(K8<>"",J8<>""),"是",IF(OR(G8<>"",F8<>""),"否","")) | L8: LeetCode 会员题（可在 neetcode.io 找同名题练习）
A9: 1 | B9: Array & Hashing 数组与哈希 | C9: 238 | D9: Product of Array Except Self | E9: Medium | F9: 46311 | I9: =IF(OR(K9<>"",J9<>""),"是",IF(OR(G9<>"",F9<>""),"否",""))
A10: 1 | B10: Array & Hashing 数组与哈希 | C10: 36 | D10: Valid Sudoku | E10: Medium | F10: 46311 | I10: =IF(OR(K10<>"",J10<>""),"是",IF(OR(G10<>"",F10<>""),"否",""))
A11: 1 | B11: Array & Hashing 数组与哈希 | C11: 128 | D11: Longest Consecutive Sequence | E11: Medium | F11: 46313 | I11: =IF(OR(K11<>"",J11<>""),"是",IF(OR(G11<>"",F11<>""),"否",""))
A12: 1 | B12: Two Pointers 双指针 | C12: 15 | D12: 3Sum | E12: Medium | I12: =IF(OR(K12<>"",J12<>""),"是",IF(OR(G12<>"",F12<>""),"否",""))
A13: 1 | B13: Two Pointers 双指针 | C13: 11 | D13: Container With Most Water | E13: Medium | I13: =IF(OR(K13<>"",J13<>""),"是",IF(OR(G13<>"",F13<>""),"否",""))
A14: 1 | B14: Two Pointers 双指针 | C14: 42 | D14: Trapping Rain Water | E14: Hard | I14: =IF(OR(K14<>"",J14<>""),"是",IF(OR(G14<>"",F14<>""),"否",""))
A15: 1 | B15: Two Pointers 双指针 | C15: 75 | D15: Sort Colors | E15: Medium | I15: =IF(OR(K15<>"",J15<>""),"是",IF(OR(G15<>"",F15<>""),"否",""))
A16: 2 | B16: Sliding Window 滑动窗口 | C16: 121 | D16: Best Time to Buy and Sell Stock | E16: Easy | F16: 46314 | I16: =IF(OR(K16<>"",J16<>""),"是",IF(OR(G16<>"",F16<>""),"否",""))
A17: 2 | B17: Sliding Window 滑动窗口 | C17: 3 | D17: Longest Substring Without Repeating Characters | E17: Medium | I17: =IF(OR(K17<>"",J17<>""),"是",IF(OR(G17<>"",F17<>""),"否",""))
A18: 2 | B18: Sliding Window 滑动窗口 | C18: 424 | D18: Longest Repeating Character Replacement | E18: Medium | I18: =IF(OR(K18<>"",J18<>""),"是",IF(OR(G18<>"",F18<>""),"否",""))
A19: 2 | B19: Sliding Window 滑动窗口 | C19: 567 | D19: Permutation in String | E19: Medium | I19: =IF(OR(K19<>"",J19<>""),"是",IF(OR(G19<>"",F19<>""),"否",""))
A20: 2 | B20: Sliding Window 滑动窗口 | C20: 76 | D20: Minimum Window Substring | E20: Hard | I20: =IF(OR(K20<>"",J20<>""),"是",IF(OR(G20<>"",F20<>""),"否",""))
A21: 2 | B21: Sliding Window 滑动窗口 | C21: 239 | D21: Sliding Window Maximum | E21: Hard | I21: =IF(OR(K21<>"",J21<>""),"是",IF(OR(G21<>"",F21<>""),"否",""))
A22: 2 | B22: Sliding Window 滑动窗口 | C22: 438 | D22: Find All Anagrams in a String | E22: Medium | I22: =IF(OR(K22<>"",J22<>""),"是",IF(OR(G22<>"",F22<>""),"否",""))
A23: 2 | B23: Stack 栈 | C23: 20 | D23: Valid Parentheses | E23: Easy | I23: =IF(OR(K23<>"",J23<>""),"是",IF(OR(G23<>"",F23<>""),"否",""))
A24: 2 | B24: Stack 栈 | C24: 232 | D24: Implement Queue using Stacks | E24: Easy | I24: =IF(OR(K24<>"",J24<>""),"是",IF(OR(G24<>"",F24<>""),"否",""))
A25: 2 | B25: Stack 栈 | C25: 155 | D25: Min Stack | E25: Medium | I25: =IF(OR(K25<>"",J25<>""),"是",IF(OR(G25<>"",F25<>""),"否",""))
A26: 2 | B26: Stack 栈 | C26: 150 | D26: Evaluate Reverse Polish Notation | E26: Medium | I26: =IF(OR(K26<>"",J26<>""),"是",IF(OR(G26<>"",F26<>""),"否",""))
A27: 2 | B27: Stack 栈 | C27: 22 | D27: Generate Parentheses | E27: Medium | I27: =IF(OR(K27<>"",J27<>""),"是",IF(OR(G27<>"",F27<>""),"否",""))
A28: 2 | B28: Stack 栈 | C28: 739 | D28: Daily Temperatures | E28: Medium | I28: =IF(OR(K28<>"",J28<>""),"是",IF(OR(G28<>"",F28<>""),"否",""))
... A90: 6 | B90: Graphs 图论 | C90: 133 | D90: Clone Graph | E90: Medium | I90: =IF(OR(K90<>"",J90<>""),"是",IF(OR(G90<>"",F90<>""),"否",""))
A91: 6 | B91: Graphs 图论 | C91: 286 | D91: Walls and Gates | E91: Medium | I91: =IF(OR(K91<>"",J91<>""),"是",IF(OR(G91<>"",F91<>""),"否","")) | L91: LeetCode 会员题（可在 neetcode.io 找同名题练习）
A92: 6 | B92: Graphs 图论 | C92: 994 | D92: Rotting Oranges | E92: Medium | I92: =IF(OR(K92<>"",J92<>""),"是",IF(OR(G92<>"",F92<>""),"否",""))
A93: 6 | B93: Graphs 图论 | C93: 417 | D93: Pacific Atlantic Water Flow | E93: Medium | I93: =IF(OR(K93<>"",J93<>""),"是",IF(OR(G93<>"",F93<>""),"否",""))
A94: 6 | B94: Graphs 图论 | C94: 130 | D94: Surrounded Regions | E94: Medium | I94: =IF(OR(K94<>"",J94<>""),"是",IF(OR(G94<>"",F94<>""),"否",""))
A95: 6 | B95: Graphs 图论 | C95: 207 | D95: Course Schedule | E95: Medium | I95: =IF(OR(K95<>"",J95<>""),"是",IF(OR(G95<>"",F95<>""),"否",""))
A96: 6 | B96: Graphs 图论 | C96: 210 | D96: Course Schedule II | E96: Medium | I96: =IF(OR(K96<>"",J96<>""),"是",IF(OR(G96<>"",F96<>""),"否",""))
A97: 6 | B97: Graphs 图论 | C97: 684 | D97: Redundant Connection | E97: Medium | I97: =IF(OR(K97<>"",J97<>""),"是",IF(OR(G97<>"",F97<>""),"否",""))
A98: 6 | B98: Graphs 图论 | C98: 323 | D98: Number of Connected Components in an Undirected Graph | E98: Medium | I98: =IF(OR(K98<>"",J98<>""),"是",IF(OR(G98<>"",F98<>""),"否","")) | L98: LeetCode 会员题（可在 neetcode.io 找同名题练习）
A99: 6 | B99: Graphs 图论 | C99: 261 | D99: Graph Valid Tree | E99: Medium | I99: =IF(OR(K99<>"",J99<>""),"是",IF(OR(G99<>"",F99<>""),"否","")) | L99: LeetCode 会员题（可在 neetcode.io 找同名题练习）
A100: 6 | B100: Graphs 图论 | C100: 127 | D100: Word Ladder | E100: Hard | I100: =IF(OR(K100<>"",J100<>""),"是",IF(OR(G100<>"",F100<>""),"否",""))
A101: 6 | B101: Graphs 图论 | C101: 752 | D101: Open the Lock | E101: Medium | I101: =IF(OR(K101<>"",J101<>""),"是",IF(OR(G101<>"",F101<>""),"否",""))
...

Sheet 进度总览
A1: NeetCode 150 刷题进度总览
A2: 所有数字由“刷题记录”自动计算，无需手动修改。
A4: 总题数 | B4: =COUNTA(刷题记录!$C$2:$C$165)
A5: 一刷完成题数 | B5: =SUMPRODUCT(--(((刷题记录!$F$2:$F$165<>"")+(刷题记录!$G$2:$G$165<>""))>0))
A6: 一刷完成率 | B6: =IFERROR(B5/B4,0)
A7: 二刷完成题数 | B7: =COUNT(刷题记录!$K$2:$K$165)
A8: 二刷完成率 | B8: =IFERROR(B7/B4,0)
A9: 一刷累计用时（小时） | B9: =SUM(刷题记录!$G$2:$G$165)/60
A10: 二刷累计用时（小时） | B10: =SUM(刷题记录!$K$2:$K$165)/60
A11: 一刷平均用时（分钟/题） | B11: =IFERROR(AVERAGE(刷题记录!$G$2:$G$165),"")
A12: 二刷平均用时（分钟/题） | B12: =IFERROR(AVERAGE(刷题记录!$K$2:$K$165),"")
A13: 黄标题数（有困难，待复盘） | B13: =COUNTIF(刷题记录!$H$2:$H$165,"有困难(黄)")
A14: 红标题数（看了答案，待复盘） | B14: =COUNTIF(刷题记录!$H$2:$H$165,"看了答案(红)")
A16: 按模块
A17: 模块 | B17: 总题数 | C17: 一刷完成 | D17: 一刷完成率 | E17: 二刷完成 | F17: 二刷完成率 | G17: 一刷平均用时(分钟) | H17: 二刷平均用时(分钟)
A18: Array & Hashing 数组与哈希 | B18: =COUNTIF(刷题记录!$B$2:$B$165,A18) | C18: =SUMPRODUCT((刷题记录!$B$2:$B$165=A18)*(((刷题记录!$F$2:$F$165<>"")+(刷题记录!$G$2:$G$165<>""))>0)) | D18: =IFERROR(C18/B18,0) | E18: =COUNTIFS(刷题记录!$B$2:$B$165,A18,刷题记录!$K$2:$K$165,">0") | F18: =IFERROR(E18/B18,0) | G18: =IFERROR(AVERAGEIFS(刷题记录!$G$2:$G$165,刷题记录!$B$2:$B$165,A18,刷题记录!$G$2:$G$165,">0"),"") | H18: =IFERROR(AVERAGEIFS(刷题记录!$K$2:$K$165,刷题记录!$B$2:$B$165,A18,刷题记录!$K$2:$K$165,">0"),"")
A19: Two Pointers 双指针 | B19: =COUNTIF(刷题记录!$B$2:$B$165,A19) | C19: =SUMPRODUCT((刷题记录!$B$2:$B$165=A19)*(((刷题记录!$F$2:$F$165<>"")+(刷题记录!$G$2:$G$165<>""))>0)) | D19: =IFERROR(C19/B19,0) | E19: =COUNTIFS(刷题记录!$B$2:$B$165,A19,刷题记录!$K$2:$K$165,">0") | F19: =IFERROR(E19/B19,0) | G19: =IFERROR(AVERAGEIFS(刷题记录!$G$2:$G$165,刷题记录!$B$2:$B$165,A19,刷题记录!$G$2:$G$165,">0"),"") | H19: =IFERROR(AVERAGEIFS(刷题记录!$K$2:$K$165,刷题记录!$B$2:$B$165,A19,刷题记录!$K$2:$K$165,">0"),"")
A20: Sliding Window 滑动窗口 | B20: =COUNTIF(刷题记录!$B$2:$B$165,A20) | C20: =SUMPRODUCT((刷题记录!$B$2:$B$165=A20)*(((刷题记录!$F$2:$F$165<>"")+(刷题记录!$G$2:$G$165<>""))>0)) | D20: =IFERROR(C20/B20,0) | E20: =COUNTIFS(刷题记录!$B$2:$B$165,A20,刷题记录!$K$2:$K$165,">0") | F20: =IFERROR(E20/B20,0) | G20: =IFERROR(AVERAGEIFS(刷题记录!$G$2:$G$165,刷题记录!$B$2:$B$165,A20,刷题记录!$G$2:$G$165,">0"),"") | H20: =IFERROR(AVERAGEIFS(刷题记录!$K$2:$K$165,刷题记录!$B$2:$B$165,A20,刷题记录!$K$2:$K$165,">0"),"")
A21: Stack 栈 | B21: =COUNTIF(刷题记录!$B$2:$B$165,A21) | C21: =SUMPRODUCT((刷题记录!$B$2:$B$165=A21)*(((刷题记录!$F$2:$F$165<>"")+(刷题记录!$G$2:$G$165<>""))>0)) | D21: =IFERROR(C21/B21,0) | E21: =COUNTIFS(刷题记录!$B$2:$B$165,A21,刷题记录!$K$2:$K$165,">0") | F21: =IFERROR(E21/B21,0) | G21: =IFERROR(AVERAGEIFS(刷题记录!$G$2:$G$165,刷题记录!$B$2:$B$165,A21,刷题记录!$G$2:$G$165,">0"),"") | H21: =IFERROR(AVERAGEIFS(刷题记录!$K$2:$K$165,刷题记录!$B$2:$B$165,A21,刷题记录!$K$2:$K$165,">0"),"")
A22: Binary Search 二分查找 | B22: =COUNTIF(刷题记录!$B$2:$B$165,A22) | C22: =SUMPRODUCT((刷题记录!$B$2:$B$165=A22)*(((刷题记录!$F$2:$F$165<>"")+(刷题记录!$G$2:$G$165<>""))>0)) | D22: =IFERROR(C22/B22,0) | E22: =COUNTIFS(刷题记录!$B$2:$B$165,A22,刷题记录!$K$2:$K$165,">0") | F22: =IFERROR(E22/B22,0) | G22: =IFERROR(AVERAGEIFS(刷题记录!$G$2:$G$165,刷题记录!$B$2:$B$165,A22,刷题记录!$G$2:$G$165,">0"),"") | H22: =IFERROR(AVERAGEIFS(刷题记录!$K$2:$K$165,刷题记录!$B$2:$B$165,A22,刷题记录!$K$2:$K$165,">0"),"")
A23: Linked List 链表 | B23: =COUNTIF(刷题记录!$B$2:$B$165,A23) | C23: =SUMPRODUCT((刷题记录!$B$2:$B$165=A23)*(((刷题记录!$F$2:$F$165<>"")+(刷题记录!$G$2:$G$165<>""))>0)) | D23: =IFERROR(C23/B23,0) | E23: =COUNTIFS(刷题记录!$B$2:$B$165,A23,刷题记录!$K$2:$K$165,">0") | F23: =IFERROR(E23/B23,0) | G23: =IFERROR(AVERAGEIFS(刷题记录!$G$2:$G$165,刷题记录!$B$2:$B$165,A23,刷题记录!$G$2:$G$165,">0"),"") | H23: =IFERROR(AVERAGEIFS(刷题记录!$K$2:$K$165,刷题记录!$B$2:$B$165,A23,刷题记录!$K$2:$K$165,">0"),"")
A24: Trees 二叉树 | B24: =COUNTIF(刷题记录!$B$2:$B$165,A24) | C24: =SUMPRODUCT((刷题记录!$B$2:$B$165=A24)*(((刷题记录!$F$2:$F$165<>"")+(刷题记录!$G$2:$G$165<>""))>0)) | D24: =IFERROR(C24/B24,0) | E24: =COUNTIFS(刷题记录!$B$2:$B$165,A24,刷题记录!$K$2:$K$165,">0") | F24: =IFERROR(E24/B24,0) | G24: =IFERROR(AVERAGEIFS(刷题记录!$G$2:$G$165,刷题记录!$B$2:$B$165,A24,刷题记录!$G$2:$G$165,">0"),"") | H24: =IFERROR(AVERAGEIFS(刷题记录!$K$2:$K$165,刷题记录!$B$2:$B$165,A24,刷题记录!$K$2:$K$165,">0"),"")
A25: Tries 字典树 | B25: =COUNTIF(刷题记录!$B$2:$B$165,A25) | C25: =SUMPRODUCT((刷题记录!$B$2:$B$165=A25)*(((刷题记录!$F$2:$F$165<>"")+(刷题记录!$G$2:$G$165<>""))>0)) | D25: =IFERROR(C25/B25,0) | E25: =COUNTIFS(刷题记录!$B$2:$B$165,A25,刷题记录!$K$2:$K$165,">0") | F25: =IFERROR(E25/B25,0) | G25: =IFERROR(AVERAGEIFS(刷题记录!$G$2:$G$165,刷题记录!$B$2:$B$165,A25,刷题记录!$G$2:$G$165,">0"),"") | H25: =IFERROR(AVERAGEIFS(刷题记录!$K$2:$K$165,刷题记录!$B$2:$B$165,A25,刷题记录!$K$2:$K$165,">0"),"")
A26: Heap / Priority Queue 堆 | B26: =COUNTIF(刷题记录!$B$2:$B$165,A26) | C26: =SUMPRODUCT((刷题记录!$B$2:$B$165=A26)*(((刷题记录!$F$2:$F$165<>"")+(刷题记录!$G$2:$G$165<>""))>0)) | D26: =IFERROR(C26/B26,0) | E26: =COUNTIFS(刷题记录!$B$2:$B$165,A26,刷题记录!$K$2:$K$165,">0") | F26: =IFERROR(E26/B26,0) | G26: =IFERROR(AVERAGEIFS(刷题记录!$G$2:$G$165,刷题记录!$B$2:$B$165,A26,刷题记录!$G$2:$G$165,">0"),"") | H26: =IFERROR(AVERAGEIFS(刷题记录!$K$2:$K$165,刷题记录!$B$2:$B$165,A26,刷题记录!$K$2:$K$165,">0"),"")
A27: Backtracking 回溯 | B27: =COUNTIF(刷题记录!$B$2:$B$165,A27) | C27: =SUMPRODUCT((刷题记录!$B$2:$B$165=A27)*(((刷题记录!$F$2:$F$165<>"")+(刷题记录!$G$2:$G$165<>""))>0)) | D27: =IFERROR(C27/B27,0) | E27: =COUNTIFS(刷题记录!$B$2:$B$165,A27,刷题记录!$K$2:$K$165,">0") | F27: =IFERROR(E27/B27,0) | G27: =IFERROR(AVERAGEIFS(刷题记录!$G$2:$G$165,刷题记录!$B$2:$B$165,A27,刷题记录!$G$2:$G$165,">0"),"") | H27: =IFERROR(AVERAGEIFS(刷题记录!$K$2:$K$165,刷题记录!$B$2:$B$165,A27,刷题记录!$K$2:$K$165,">0"),"")
A28: Graphs 图论 | B28: =COUNTIF(刷题记录!$B$2:$B$165,A28) | C28: =SUMPRODUCT((刷题记录!$B$2:$B$165=A28)*(((刷题记录!$F$2:$F$165<>"")+(刷题记录!$G$2:$G$165<>""))>0)) | D28: =IFERROR(C28/B28,0) | E28: =COUNTIFS(刷题记录!$B$2:$B$165,A28,刷题记录!$K$2:$K$165,">0") | F28: =IFERROR(E28/B28,0) | G28: =IFERROR(AVERAGEIFS(刷题记录!$G$2:$G$165,刷题记录!$B$2:$B$165,A28,刷题记录!$G$2:$G$165,">0"),"") | H28: =IFERROR(AVERAGEIFS(刷题记录!$K$2:$K$165,刷题记录!$B$2:$B$165,A28,刷题记录!$K$2:$K$165,">0"),"")
A29: Advanced Graphs 高级图论 | B29: =COUNTIF(刷题记录!$B$2:$B$165,A29) | C29: =SUMPRODUCT((刷题记录!$B$2:$B$165=A29)*(((刷题记录!$F$2:$F$165<>"")+(刷题记录!$G$2:$G$165<>""))>0)) | D29: =IFERROR(C29/B29,0) | E29: =COUNTIFS(刷题记录!$B$2:$B$165,A29,刷题记录!$K$2:$K$165,">0") | F29: =IFERROR(E29/B29,0) | G29: =IFERROR(AVERAGEIFS(刷题记录!$G$2:$G$165,刷题记录!$B$2:$B$165,A29,刷题记录!$G$2:$G$165,">0"),"") | H29: =IFERROR(AVERAGEIFS(刷题记录!$K$2:$K$165,刷题记录!$B$2:$B$165,A29,刷题记录!$K$2:$K$165,">0"),"")
... A35: Bit Manipulation 位运算 | B35: =COUNTIF(刷题记录!$B$2:$B$165,A35) | C35: =SUMPRODUCT((刷题记录!$B$2:$B$165=A35)*(((刷题记录!$F$2:$F$165<>"")+(刷题记录!$G$2:$G$165<>""))>0)) | D35: =IFERROR(C35/B35,0) | E35: =COUNTIFS(刷题记录!$B$2:$B$165,A35,刷题记录!$K$2:$K$165,">0") | F35: =IFERROR(E35/B35,0) | G35: =IFERROR(AVERAGEIFS(刷题记录!$G$2:$G$165,刷题记录!$B$2:$B$165,A35,刷题记录!$G$2:$G$165,">0"),"") | H35: =IFERROR(AVERAGEIFS(刷题记录!$K$2:$K$165,刷题记录!$B$2:$B$165,A35,刷题记录!$K$2:$K$165,">0"),"")
A37: 按难度
A38: 难度 | B38: 总题数 | C38: 一刷完成 | D38: 一刷完成率 | E38: 二刷完成 | F38: 二刷完成率 | G38: 一刷平均用时(分钟) | H38: 二刷平均用时(分钟)
A39: Easy | B39: =COUNTIF(刷题记录!$E$2:$E$165,A39) | C39: =SUMPRODUCT((刷题记录!$E$2:$E$165=A39)*(((刷题记录!$F$2:$F$165<>"")+(刷题记录!$G$2:$G$165<>""))>0)) | D39: =IFERROR(C39/B39,0) | E39: =COUNTIFS(刷题记录!$E$2:$E$165,A39,刷题记录!$K$2:$K$165,">0") | F39: =IFERROR(E39/B39,0) | G39: =IFERROR(AVERAGEIFS(刷题记录!$G$2:$G$165,刷题记录!$E$2:$E$165,A39,刷题记录!$G$2:$G$165,">0"),"") | H39: =IFERROR(AVERAGEIFS(刷题记录!$K$2:$K$165,刷题记录!$E$2:$E$165,A39,刷题记录!$K$2:$K$165,">0"),"")
A40: Medium | B40: =COUNTIF(刷题记录!$E$2:$E$165,A40) | C40: =SUMPRODUCT((刷题记录!$E$2:$E$165=A40)*(((刷题记录!$F$2:$F$165<>"")+(刷题记录!$G$2:$G$165<>""))>0)) | D40: =IFERROR(C40/B40,0) | E40: =COUNTIFS(刷题记录!$E$2:$E$165,A40,刷题记录!$K$2:$K$165,">0") | F40: =IFERROR(E40/B40,0) | G40: =IFERROR(AVERAGEIFS(刷题记录!$G$2:$G$165,刷题记录!$E$2:$E$165,A40,刷题记录!$G$2:$G$165,">0"),"") | H40: =IFERROR(AVERAGEIFS(刷题记录!$K$2:$K$165,刷题记录!$E$2:$E$165,A40,刷题记录!$K$2:$K$165,">0"),"")
A41: Hard | B41: =COUNTIF(刷题记录!$E$2:$E$165,A41) | C41: =SUMPRODUCT((刷题记录!$E$2:$E$165=A41)*(((刷题记录!$F$2:$F$165<>"")+(刷题记录!$G$2:$G$165<>""))>0)) | D41: =IFERROR(C41/B41,0) | E41: =COUNTIFS(刷题记录!$E$2:$E$165,A41,刷题记录!$K$2:$K$165,">0") | F41: =IFERROR(E41/B41,0) | G41: =IFERROR(AVERAGEIFS(刷题记录!$G$2:$G$165,刷题记录!$E$2:$E$165,A41,刷题记录!$G$2:$G$165,">0"),"") | H41: =IFERROR(AVERAGEIFS(刷题记录!$K$2:$K$165,刷题记录!$E$2:$E$165,A41,刷题记录!$K$2:$K$165,">0"),"")

Sheet 每周计划
A1: 10 周计划
A2: 计划开始日期（周一，可修改） | C2: 46314 | D2: ← 假设：从 2026-10-19 开始；改这一格，下面各周日期会自动更新
A4: 周 | B4: 开始日 | C4: 结束日 | D4: 内容 | E4: 计划题数 | F4: 已完成 | G4: 完成率 | H4: 平均每学习日题数（按5天） | I4: 说明
A5: 1 | B5: =$C$2+7*(A5-1) | C5: =B5+6 | D5: Array & Hashing + Two Pointers | E5: =COUNTIF(刷题记录!$A$2:$A$165,A5) | F5: =SUMPRODUCT((刷题记录!$A$2:$A$165=A5)*(((刷题记录!$F$2:$F$165<>"")+(刷题记录!$G$2:$G$165<>""))>0)) | G5: =IFERROR(F5/E5,0) | H5: =ROUND(E5/5,1) | I5: 含你提到的“哈希收尾”
A6: 2 | B6: =$C$2+7*(A6-1) | C6: =B6+6 | D6: Sliding Window + Stack | E6: =COUNTIF(刷题记录!$A$2:$A$165,A6) | F6: =SUMPRODUCT((刷题记录!$A$2:$A$165=A6)*(((刷题记录!$F$2:$F$165<>"")+(刷题记录!$G$2:$G$165<>""))>0)) | G6: =IFERROR(F6/E6,0) | H6: =ROUND(E6/5,1)
A7: 3 | B7: =$C$2+7*(A7-1) | C7: =B7+6 | D7: Binary Search + Linked List | E7: =COUNTIF(刷题记录!$A$2:$A$165,A7) | F7: =SUMPRODUCT((刷题记录!$A$2:$A$165=A7)*(((刷题记录!$F$2:$F$165<>"")+(刷题记录!$G$2:$G$165<>""))>0)) | G7: =IFERROR(F7/E7,0) | H7: =ROUND(E7/5,1)
A8: 4 | B8: =$C$2+7*(A8-1) | C8: =B8+6 | D8: Trees | E8: =COUNTIF(刷题记录!$A$2:$A$165,A8) | F8: =SUMPRODUCT((刷题记录!$A$2:$A$165=A8)*(((刷题记录!$F$2:$F$165<>"")+(刷题记录!$G$2:$G$165<>""))>0)) | G8: =IFERROR(F8/E8,0) | H8: =ROUND(E8/5,1)
A9: 5 | B9: =$C$2+7*(A9-1) | C9: =B9+6 | D9: Tries + Heap + Backtracking | E9: =COUNTIF(刷题记录!$A$2:$A$165,A9) | F9: =SUMPRODUCT((刷题记录!$A$2:$A$165=A9)*(((刷题记录!$F$2:$F$165<>"")+(刷题记录!$G$2:$G$165<>""))>0)) | G9: =IFERROR(F9/E9,0) | H9: =ROUND(E9/5,1)
A10: 6 | B10: =$C$2+7*(A10-1) | C10: =B10+6 | D10: Graphs | E10: =COUNTIF(刷题记录!$A$2:$A$165,A10) | F10: =SUMPRODUCT((刷题记录!$A$2:$A$165=A10)*(((刷题记录!$F$2:$F$165<>"")+(刷题记录!$G$2:$G$165<>""))>0)) | G10: =IFERROR(F10/E10,0) | H10: =ROUND(E10/5,1)
A11: 7 | B11: =$C$2+7*(A11-1) | C11: =B11+6 | D11: Advanced Graphs | E11: =COUNTIF(刷题记录!$A$2:$A$165,A11) | F11: =SUMPRODUCT((刷题记录!$A$2:$A$165=A11)*(((刷题记录!$F$2:$F$165<>"")+(刷题记录!$G$2:$G$165<>""))>0)) | G11: =IFERROR(F11/E11,0) | H11: =ROUND(E11/5,1) | I11: 题量较少，可当缓冲周
A12: 8 | B12: =$C$2+7*(A12-1) | C12: =B12+6 | D12: 1-D DP + 2-D DP | E12: =COUNTIF(刷题记录!$A$2:$A$165,A12) | F12: =SUMPRODUCT((刷题记录!$A$2:$A$165=A12)*(((刷题记录!$F$2:$F$165<>"")+(刷题记录!$G$2:$G$165<>""))>0)) | G12: =IFERROR(F12/E12,0) | H12: =ROUND(E12/5,1) | I12: 题量较大，难题多
A13: 9 | B13: =$C$2+7*(A13-1) | C13: =B13+6 | D13: Greedy + Intervals + Math & Geometry + Bit Manipulation | E13: =COUNTIF(刷题记录!$A$2:$A$165,A13) | F13: =SUMPRODUCT((刷题记录!$A$2:$A$165=A13)*(((刷题记录!$F$2:$F$165<>"")+(刷题记录!$G$2:$G$165<>""))>0)) | G13: =IFERROR(F13/E13,0) | H13: =ROUND(E13/5,1) | I13: 题量较大，但多为简单和中等题
A14: 10 | B14: =$C$2+7*(A14-1) | C14: =B14+6 | D14: 错题复盘与模拟：重做黄标 / 红标题 | E14: =COUNTIF(刷题记录!$H$2:$H$165,"有困难(黄)")+COUNTIF(刷题记录!$H$2:$H$165,"看了答案(红)") | F14: =COUNTIFS(刷题记录!$H$2:$H$165,"有困难(黄)",刷题记录!$K$2:$K$165,">0")+COUNTIFS(刷题记录!$H$2:$H$165,"看了答案(红)",刷题记录!$K$2:$K$165,">0") | G14: =IFERROR(F14/E14,0) | H14: =ROUND(E14/5,1) | I14: 第 10 周：计划题数 = 当前黄标 + 红标题数；已完成 = 其中已有二刷用时的题数
D15: 合计（第 1–9 周） | E15: =SUM(E5:E13) | F15: =SUM(F5:F13) | G15: =IFERROR(F15/E15,0)

Sheet 使用说明
A1: 使用说明
A2: 橙色表头的列 | B2: 需要你手动填写：一刷日期、一刷用时(分钟)、掌握度、二刷日期、二刷用时(分钟)、备注。浅黄色底的单元格就是填写区。
A3: 蓝色表头的列 | B3: 已预先填好：周、模块、题目编号（即 LeetCode 题号）、题名、难度。
A4: 是否二刷 | B4: 自动显示：填了二刷日期或二刷用时显示“是”；只做过一刷显示“否”；还没开始则留空。不用手动填。
A5: 掌握度 | B5: 下拉选择：顺利 / 有困难(黄) / 看了答案(红)。第 10 周复盘时，用表头筛选按钮选出黄标和红标题重做。
A6: 进度总览 / 每周计划 | B6: 自动汇总，不需要修改。每周计划里的开始日期可以改。
A7: 题单来源与假设 | B7: 题单已改为你在 LeetCode 上的清单(164 题),按 NeetCode 的模块顺序排列,每周分配沿用原 10 周计划。清单里没有的 NeetCode 题(50、125、136、167、206、287)已删除;清单里原先没有分类的题(如 752、1235、542 等 20 题)按题型归入最接近的模块。
A8: 周分配 | B8: 每周题量按模块自动统计(见“每周计划”)。需要调整时改“刷题记录”的“周”列,每周计划会自动重新统计。
A9: 会员题 | B9: 备注里标了“LeetCode 会员题”的有 7 道（271、286、323、261、269、252、253）。
A10: 填写示例（仅示意格式，不在数据里）
A11: 题目编号 | B11: 题名 | C11: 一刷日期 | D11: 一刷用时(分钟) | E11: 掌握度 | F11: 是否二刷（自动）
A12: 1 | B12: Two Sum | C12: 46314 | D12: 18 | E12: 顺利 | F12: 否
